Workbook

Sheet 基础信息表
B1: 计控课设-团队信息表
B2: 填表说明：表格杏色底纹部分填写内容，其余不用动。
B3: 项目名称：
B5: 团队编号 | C5: 团队角色 | D5: 姓名 | E5: 学号 | F5: 班级
B6: 0901 | C6: 负责人 | F6: 自动化2301
B7: 指导教师 | C7: 成员1 | F7: 自动化2301
B8: 王艳辉 | C8: 成员2 | F8: 自动化2301
C9: … | D9: … | E9: … | F9: …
B11: 指导教师签名 | C11: =_xlfn.DISPIMG("ID_A08B1BBDD01046CB8B5D1E00D71465ED",1) -> =DISPIMG("ID_A08B1BBDD01046CB8B5D1E00D71465ED",1)
B12: 答辩组签名 | C12: =_xlfn.DISPIMG("ID_1F1695394C5D4F30B6211CC67EB5DEA1",1) -> =DISPIMG("ID_1F1695394C5D4F30B6211CC67EB5DEA1",1)
B14: 表单签字时间
B15: 考核环节 | C15: 过程评分 | D15: 答辩评分 | E15: 团队自评互评 | F15: 成绩评定
B16: 签字日期 | C16: 46211 | D16: 46212 | E16: 46212 | F16: 46213
B18: 本工作簿表单用途说明
B19: 序号 | C19: 表单名称 | D19: 用途
B20: 1 | C20: 基础信息表 | D20: 填写杏色底纹单元格，包括团队编号、指导教师和学生信息，签名采用将图片嵌入单元格的形式。
B21: 2 | C21: 过程评分表 | D21: 仅填写评分，即杏色底纹单元格。
B22: 3 | C22: 答辩评分表 | D22: 仅填写评分，即杏色底纹单元格。
B23: 4 | C23: 团队合作 自评-互评表 | D23: 将学生的打分表评分录入表格中
B24: 5 | C24: 成绩评定单 | D24: 自动生成，用于生成PDF文件作为电子存档文件。
B25: 6 | C25: 信息汇总表 | D25: 自动生成，仅有复制功能，用于填写负责人提供的成绩、达成度等汇总表格。
B26: 最后将表单2、3、4、5生成PDF电子文档用于归档，命名规范如下：
B27: 一个团队所有文档统一存放于一个文件夹中。 文件夹命名格式为“团队成绩-团队编号-课设题目-自动化-计控课设2026”，示例如下图所示。 文件夹内仅需存放PDF格式文档，Word版本由指导教师自行留存备用。 文件夹下需包含以下pdf文档，签名部分确保不漏，文档命名规则如下： 1-团队编号-任务书-自动化-计控课设2026 2-团队编号-分工表-自动化-计控课设2026 3-团队编号-会议纪要-自动化-计控课设2026 4-团队编号-课设报告-自动化-计控课设2026 5-团队编号-过程评分表-自动化-计控课设2026 6-团队编号-答辩评分表-自动化-计控课设2026 7-团队编号-自评互评表-自动化-计控课设2026 8-团队编号-成绩评定表-自动化-计控课设2026 9-团队编号-成员贡献表-自动化-计控课设2026

Sheet 过程评分表
A1: 沈阳航空航天大学自动化学院
A2: 计算机控制综合课程设计 过程评分表
A3: 填报说明：指导教师只需要在杏色评分区域填写权重值1即可。
A4: 项目名称： | C4: =基础信息表!C3 -> 0
A5: 团队角色： | C5: =基础信息表!C6 -> 负责人 | D5: 团队编号： | F5: =基础信息表!B6 -> 0901
A6: 姓 名： | C6: =基础信息表!D6 -> 0 | D6: 学 号： | F6: =基础信息表!E6 -> 0 | I6: 班级： | K6: =基础信息表!F6 -> 自动化2301
A8: 课程 目标 | B8: 评价内容 | C8: 具体要求 | F8: 权重 | G8: 评分 | K8: 加权分
G9: 5 | H9: 4 | I9: 3 | J9: 2
A10: 1 | B10: 问题分析 | C10: 查阅文献、资料，获取有效信息；理解课设任务要求并正确描述，明确制约条件，寻找解决复杂工程问题的方法，并得到有效解。 | F10: 0.2 | H10: 1 | K10: =F10*(G10*$G$9+$H$9*H10+$I$9*I10+$J$9*J10) -> 0.8
A11: 2 | B11: 解决方案 | C11: 能够综合运用专业理论和技术手段设计针对自动控制领域复杂工程问题的解决方案。方案设计自主性良好，理论正确，切实可行。 | E11: 目标1 目标2 | F11: 0.4 | H11: 1 | K11: =F11*(G11*$G$9+$H$9*H11+$I$9*I11+$J$9*J11) -> 1.6
A12: 3 | B12: 方案设计中综合因素的考虑 | C12: 能够在设计过程中综合考虑社会、健康、安全、法律、文化及环境等因素。 | E12: 目标1 目标2 | F12: 0.1 | H12: 1 | K12: =F12*(G12*$G$9+$H$9*H12+$I$9*I12+$J$9*J12) -> 0.4
A13: 4 | B13: 团队协作 | C13: 明确个人分工、履行个人职责、对团队成果的贡献。 | F13: 0.1 | G13: 1 | K13: =F13*(G13*$G$9+$H$9*H13+$I$9*I13+$J$9*J13) -> 0.5
A14: 5 | C14: 主动沟通、配合团队安排、协调与支持他人、团队责任意识。 | F14: 0.1 | G14: 1 | K14: =F14*(G14*$G$9+$H$9*H14+$I$9*I14+$J$9*J14) -> 0.5
A15: 6 | B15: 项目管理 | C15: 课程设计过程能够综合考虑经济和管理因素，项目进度计划合理，经济可行。 | E15: 目标3 | F15: 0.1 | H15: 1 | K15: =F15*(G15*$G$9+$H$9*H15+$I$9*I15+$J$9*J15) -> 0.4
A16: 课设过程考核总分(低于3分的学生取消课设答辩资格) | K16: =SUM(K10:K15) -> 4.2
E18: 指导教师（签字）： | I18: =基础信息表!C11 -> =DISPIMG("ID_A08B1BBDD01046CB8B5D1E00D71465ED",1)
F19: =基础信息表!C16 -> 46211
A20: 沈阳航空航天大学自动化学院
A21: 计算机控制综合课程设计 过程评分表
A22: 填报说明：指导教师只需要在杏色评分区域填写权重值1即可。
A23: 项目名称： | C23: =基础信息表!C3 -> 0
A24: 团队角色： | C24: =基础信息表!C7 -> 成员1 | D24: 团队编号： | F24: =基础信息表!B6 -> 0901
A25: 姓 名： | C25: =基础信息表!D7 -> 0 | D25: 学 号： | F25: =基础信息表!E7 -> 0 | I25: 班级： | K25: =基础信息表!F6 -> 自动化2301
A27: 课程 目标 | B27: 评价内容 | C27: 具体要求 | F27: 权重 | G27: 评分 | K27: 加权分
G28: 5 | H28: 4 | I28: 3 | J28: 2
A29: 1 | B29: 问题分析 | C29: 查阅文献、资料，获取有效信息；理解课设任务要求并正确描述，明确制约条件，寻找解决复杂工程问题的方法，并得到有效解。 | F29: 0.2 | H29: 1 | K29: =F29*(G29*$G$9+$H$9*H29+$I$9*I29+$J$9*J29) -> 0.8
A30: 2 | B30: 解决方案 | C30: 能够综合运用专业理论和技术手段设计针对自动控制领域复杂工程问题的解决方案。方案设计自主性良好，理论正确，切实可行。 | E30: 目标1 目标2 | F30: 0.4 | H30: 1 | K30: =F30*(G30*$G$9+$H$9*H30+$I$9*I30+$J$9*J30) -> 1.6
A31: 3 | B31: 方案设计中综合因素的考虑 | C31: 能够在设计过程中综合考虑社会、健康、安全、法律、文化及环境等因素。 | E31: 目标1 目标2 | F31: 0.1 | H31: 1 | K31: =F31*(G31*$G$9+$H$9*H31+$I$9*I31+$J$9*J31) -> 0.4
A32: 4 | B32: 团队协作 | C32: 明确个人分工、履行个人职责、对团队成果的贡献。 | F32: 0.1 | G32: 1 | K32: =F32*(G32*$G$9+$H$9*H32+$I$9*I32+$J$9*J32) -> 0.5
A33: 5 | C33: 主动沟通、配合团队安排、协调与支持他人、团队责任意识。 | F33: 0.1 | G33: 1 | K33: =F33*(G33*$G$9+$H$9*H33+$I$9*I33+$J$9*J33) -> 0.5
A34: 6 | B34: 项目管理 | C34: 课程设计过程能够综合考虑经济和管理因素，项目进度计划合理，经济可行。 | E34: 目标3 | F34: 0.1 | H34: 1 | K34: =F34*(G34*$G$9+$H$9*H34+$I$9*I34+$J$9*J34) -> 0.4
A35: 课设过程考核总分(低于3分的学生取消课设答辩资格) | K35: =SUM(K29:K34) -> 4.2
E37: 指导教师（签字）： | I37: =基础信息表!C11 -> =DISPIMG("ID_A08B1BBDD01046CB8B5D1E00D71465ED",1)
F38: =F19 -> 46211
A39: 沈阳航空航天大学自动化学院
A40: 计算机控制综合课程设计 过程评分表
A41: 填表说明：指导教师只需要在杏色评分区域填写权重值1即可。
A42: 项目名称： | C42: =基础信息表!C3 -> 0
A43: 团队角色： | C43: =基础信息表!C8 -> 成员2 | D43: 团队编号： | F43: =基础信息表!B6 -> 0901
A44: 姓 名： | C44: =基础信息表!D8 -> 0 | D44: 学 号： | F44: =基础信息表!E8 -> 0 | I44: 班级： | K44: =基础信息表!F8 -> 自动化2301
...

Sheet 答辩评分表  
A1: 沈阳航空航天大学自动化学院
A2: 计算机控制综合课程设计 答辩评分表
A3: 说明：只需在杏色评分区域填写权重1，该表是对整个团队进行评分的。
A4: 项目名称 | C4: =基础信息表!C3 -> 0
A5: 团队编号 | C5: 团队角色 | D5: 姓名 | E5: 学号 | J5: 班级
A6: =基础信息表!B6 -> 0901 | C6: =基础信息表!C6 -> 负责人 | D6: =基础信息表!D6 -> 0 | E6: =基础信息表!E6 -> 0 | F6: 自动化2102 | J6: =基础信息表!F6 -> 自动化2301
A7: 指导教师 | C7: =基础信息表!C7 -> 成员1 | D7: =基础信息表!D7 -> 0 | E7: =基础信息表!E7 -> 0 | F7: 自动化2102 | J7: =基础信息表!F7 -> 自动化2301
A8: =基础信息表!B8 -> 王艳辉 | C8: =基础信息表!C8 -> 成员2 | D8: =基础信息表!D8 -> 0 | E8: =基础信息表!E8 -> 0 | F8: 自动化2102 | J8: =基础信息表!F8 -> 自动化2301
A10: 课程 目标 | B10: 评价内容 | C10: 具体要求 | E10: 权重 | F10: 评分 | J10: 加权分
F11: 5 | G11: 4 | H11: 3 | I11: 2
A12: 1 | B12: 问题分析 | C12: 答辩过程中，能够理解课设任务并正确描述，明确任务分工，方案可行。 | E12: 0.2 | G12: 1 | J12: =E12*(F12*$F$11+$G$11*G12+$H$11*H12+$I$11*I12) -> 0.8
A13: 2 | B13: 解决方案 | C13: 答辩PPT，能够综合运用专业理论和技术手段设计针对自动控制领域复杂工程问题的解决方案。软硬件方案设计良好，理论正确。实验或仿真结果分析正确。 | E13: 0.4 | H13: 1 | J13: =E13*(F13*$F$11+$G$11*G13+$H$11*H13+$I$11*I13) -> 1.2
A14: 3 | B14: 方案设计中综合因素的考虑 | C14: 能够在设计过程中综合考虑社会、健康、安全、法律、文化及环境等因素。 | E14: 0.1 | G14: 1 | J14: =E14*(F14*$F$11+$G$11*G14+$H$11*H14+$I$11*I14) -> 0.4
A15: 4 | B15: 团队协作 | C15: 明确个人分工、履行个人职责、对团队成果的贡献 | E15: 0.1 | H15: 1 | J15: =E15*(F15*$F$11+$G$11*G15+$H$11*H15+$I$11*I15) -> 0.3
A16: 5 | C16: 主动沟通、配合团队安排、协调与支持他人、团队责任意识 | E16: 0.1 | G16: 1 | J16: =E16*(F16*$F$11+$G$11*G16+$H$11*H16+$I$11*I16) -> 0.4
A17: 6 | B17: 项目管理 | C17: 课程设计过程团队整体都能够综合考虑经济和管理因素，项目进度计划合理，经济可行。 | E17: 0.1 | H17: 1 | J17: =E17*(F17*$F$11+$G$11*G17+$H$11*H17+$I$11*I17) -> 0.3
A18: 总分课设过程答辩总分(低于3分的学生答辩不及格) | J18: =SUM(J12:J17) -> 3.4
A20: 答辩组签字： | C20: =基础信息表!C12 -> =DISPIMG("ID_1F1695394C5D4F30B6211CC67EB5DEA1",1)
E21: =基础信息表!D16 -> 46212

Sheet 团队合作自评-互评表
A1: 计算机控制综合课程设计 团队合作自评表
A2: 团队评分计算方法：所有打分均为百分制，团队评分占课设总成绩权重为20%。 （1）团队负责人得分=负责人自评*40%+（成员对负责人评分累积和/成员人数）*60% （2）成员得分=成员自评*40%+负责人对成员员的评分*60%
A3: 团队角色： | B3: =基础信息表!C6 -> 负责人 | D3: 团队编号： | E3: 0902
A4: 项目名称： | B4: 生化培养箱控制系统设计
A5: 姓 名： | B5: 周恭瑾 | C5: 学号： | D5: 233407020330 | E5: 班级： | F5: 自动化2303
A6: 自评评分表
A7: 评价项目 | B7: 对应教学目标 /毕设指标点 | C7: 评价内容 | F7: 自评 得分 | G7: 参考 分值
A8: 角色认知 | B8: 教学目标4 / 9-1 | C8: 能否清楚认识自己在团队中的角色，明确本人承担的设计、编程、调试、报告或汇报任务。 | F8: 15 | G8: 15
A9: 职责履行 | B9: 教学目标4 / 9-1 | C9: 是否按计划完成本人承担的任务，是否存在拖延、推诿或完成质量不足的问题。 | F9: 20 | G9: 20
A10: 个人贡献 | B10: 教学目标4 / 9-1 | C10: 本人是否对系统设计、程序实现、控制调试、结果分析或报告撰写有实质贡献。 | F10: 15 | G10: 15
A11: 主动沟通 | B11: 教学目标5 / 9-2 | C11: 是否主动与团队成员交流任务进展、技术问题和工作需求。 | F11: 15 | G11: 15
A12: 配合团队安排 | B12: 教学目标5 / 9-2 | C12: 是否能够服从团队整体安排，并根据项目进度调整个人任务。 | F12: 15 | G12: 15
A13: 协调与支持 | B13: 教学目标5 / 9-2 | C13: 是否主动协助其他成员解决问题，促进任务衔接和团队推进。 | F13: 15 | G13: 15
A14: 团队责任意识 | B14: 教学目标5 / 9-2 | C14: 是否关注团队整体目标，维护团队合作氛围和项目完成质量。 | F14: 5 | G14: 5
A15: 合计： | F15: =SUM(F8:F14) -> 100 | G15: =SUM(G8:G14) -> 100
A17: 自评分项统计
A18: 教学目标 | B18: 对应指标点 | C18: 对应评价项目 | F18: 得分 | G18: 满分
A19: 教学目标4 | B19: 9-1 | C19: 角色认知、职责履行、个人贡献 | F19: =SUM(F8:F10) -> 50 | G19: 50
A20: 教学目标5 | B20: 9-2 | C20: 主动沟通、配合团队安排、协调与支持、团队责任意识 | F20: =SUM(F11:F14) -> 50 | G20: 50
D21: 自评日期： | F21: =基础信息表!E16 -> 46212
A22: 填表说明：自评得分应为0至对应分值之间的整数；合计和分项统计由表格自动计算。
A23: 计算机控制综合课程设计 团队合作自评表
A24: 团队评分计算方法：所有打分均为百分制，团队评分占课设总成绩权重为20%。 （1）团队负责人得分=负责人自评*40%+（成员对负责人评分累积和/成员人数）*60% （2）成员得分=成员自评*40%+负责人对成员员的评分*60%
A25: 团队角色： | B25: =基础信息表!C7 -> 成员1 | D25: 团队编号： | E25: =基础信息表!B6 -> 0901
A26: 项目名称： | B26: =基础信息表!C3 -> 0
A27: 姓 名： | B27: =基础信息表!D7 -> 0 | C27: 学号： | D27: =基础信息表!E7 -> 0 | E27: 班级： | F27: =基础信息表!F6 -> 自动化2301
A28: 自评评分表
A29: 评价项目 | B29: 对应教学目标 /毕设指标点 | C29: 评价内容 | F29: 自评 得分 | G29: 参考 分值
A30: 角色认知 | B30: 教学目标4 / 9-1 | C30: 能否清楚认识自己在团队中的角色，明确本人承担的设计、编程、调试、报告或汇报任务。 | G30: 15
A31: 职责履行 | B31: 教学目标4 / 9-1 | C31: 是否按计划完成本人承担的任务，是否存在拖延、推诿或完成质量不足的问题。 | G31: 20
A32: 个人贡献 | B32: 教学目标4 / 9-1 | C32: 本人是否对系统设计、程序实现、控制调试、结果分析或报告撰写有实质贡献。 | G32: 15
A33: 主动沟通 | B33: 教学目标5 / 9-2 | C33: 是否主动与团队成员交流任务进展、技术问题和工作需求。 | G33: 15
A34: 配合团队安排 | B34: 教学目标5 / 9-2 | C34: 是否能够服从团队整体安排，并根据项目进度调整个人任务。 | G34: 15
A35: 协调与支持 | B35: 教学目标5 / 9-2 | C35: 是否主动协助其他成员解决问题，促进任务衔接和团队推进。 | G35: 15
A36: 团队责任意识 | B36: 教学目标5 / 9-2 | C36: 是否关注团队整体目标，维护团队合作氛围和项目完成质量。 | G36: 5
A37: 合计： | F37: =SUM(F30:F36) -> 0 | G37: =SUM(G30:G36) -> 100
A39: 自评分项统计
A40: 教学目标 | B40: 对应指标点 | C40: 对应评价项目 | F40: 得分 | G40: 满分
A41: 教学目标4 | B41: 9-1 | C41: 角色认知、职责履行、个人贡献 | F41: =SUM(F30:F32) -> 0 | G41: 50
A42: 教学目标5 | B42: 9-2 | C42: 主动沟通、配合团队安排、协调与支持、团队责任意识 | F42: =SUM(F33:F36) -> 0 | G42: 50
...

Sheet 成绩评定单
A1: 沈阳航空航天大学自动化学院
A2: 计算机控制综合课程设计 成绩评定单
A4: 项目名称： | C4: =基础信息表!C3 -> 0
A5: 团队角色： | C5: =基础信息表!C6 -> 负责人 | D5: 团队编号： | F5: =基础信息表!B6 -> 0901
A6: 姓 名： | C6: =基础信息表!D6 -> 0 | D6: 学 号： | F6: =基础信息表!E6 -> 0 | I6: 班级： | K6: =基础信息表!F6 -> 自动化2301
A8: 成绩评定如下：
A9: 评价内容 | C9: 具体要求 | G9: 权重 | I9: 分值 | K9: 加权分值
A10: 过程评定 | C10: 详见课程设计过程评分表 | G10: 0.4 | I10: =过程评分表!K54 -> 3.8 | K10: =G10*I10 -> 1.52
A11: 答辩评定 | C11: 详见课程设计答辩评分表 | G11: 0.4 | I11: ='答辩评分表 '!J18 -> 3.4 | K11: =G11*I11 -> 1.36
A12: 团队评分 | C12: 详见团队合作自评互评表 | G12: 0.2 | I12: =('团队合作自评-互评表'!F15*40%+('团队合作自评-互评表'!F126+'团队合作自评-互评表'!F148)/2*60%)/20 -> 5 | K12: =G12*I12 -> 1
A13: 总成绩 | G13: =K10+K11+K12 -> 3.88
A14: 折合五级制成绩 | G14: =IF(G13>=4.5,"优秀",IF(G13>=4,"良好",IF(G13>=3.5,"中等",IF(G13>=3,"及格",IF(G13<3,"不及格"))))) -> 中等
A15: 课程教学目标得分汇总
A16: 课程目标 | C16: 1 | D16: 2 | E16: 3 | F16: 4 | H16: 5 | J16: 6
A17: 目标分值 | C17: 1 | D17: 2 | E17: 0.5 | F17: 0.5 | H17: 0.5 | J17: 0.5
A18: 得分 | C18: ='答辩评分表 '!J12*50%+过程评分表!K10*50% -> 0.8 | D18: ='答辩评分表 '!J13*50%+过程评分表!K11*50% -> 1.4 | E18: ='答辩评分表 '!J14*50%+过程评分表!K12*50% -> 0.4 | F18: ='答辩评分表 '!J15*25%+过程评分表!K13*25%+('团队合作自评-互评表'!F19*40%+'团队合作自评-互评表'!F129*30%+'团队合作自评-互评表'!F151*30%)/50*0.5*50% -> 0.45 | H18: ='答辩评分表 '!J16*25%+过程评分表!K14*25%+('团队合作自评-互评表'!F20*40%+'团队合作自评-互评表'!F130*30%+'团队合作自评-互评表'!F152*30%)/50*0.5*50% -> 0.475 | J18: ='答辩评分表 '!J17*50%+过程评分表!K15*50% -> 0.35
A20: 评语：
A21: 经过程、答辩和团队综合评定，该同学课设完成情况达到了课设任务书要求，其答辩和课设论文也达到了专业课设论文的要求，故答辩组一致同意下列的成绩。
A23: 课程设计成绩: | C23: =G14 -> 中等
A24: 指导教师(签字): | C24: =基础信息表!C11 -> =DISPIMG("ID_A08B1BBDD01046CB8B5D1E00D71465ED",1)
F26: =基础信息表!F16 -> 46213
A27: 沈阳航空航天大学自动化学院
A28: 计算机控制综合课程设计 成绩评定单
A30: 项目名称： | C30: =基础信息表!C3 -> 0
A31: 团队角色： | C31: =基础信息表!C7 -> 成员1 | D31: 团队编号： | F31: =基础信息表!B6 -> 0901
A32: 姓 名： | C32: =基础信息表!D7 -> 0 | D32: 学 号： | F32: =基础信息表!E7 -> 0 | I32: 班级： | K32: =基础信息表!F7 -> 自动化2301
A34: 成绩评定如下：
A35: 评价内容 | C35: 具体要求 | G35: 权重 | I35: 分值 | K35: 加权分值
A36: 过程评定 | C36: 详见课程设计过程评分表 | G36: 0.4 | I36: =过程评分表!K35 -> 4.2 | K36: =G36*I36 -> 1.68
A37: 答辩评定 | C37: 详见课程设计答辩评分表 | G37: 0.4 | I37: ='答辩评分表 '!J18 -> 3.4 | K37: =G37*I37 -> 1.36
A38: 团队评分 | C38: 详见团队合作自评互评表 | G38: 0.2 | I38: =('团队合作自评-互评表'!G37*40%+'团队合作自评-互评表'!G82*60%)/20 -> 5 | K38: =G38*I38 -> 1
A39: 总成绩 | G39: =K36+K37+K38 -> 4.04
A40: 折合五级制成绩 | G40: =IF(G39>=4.5,"优秀",IF(G39>=4,"良好",IF(G39>=3.5,"中等",IF(G39>=3,"及格",IF(G39<3,"不及格"))))) -> 良好
A41: 课程教学目标得分汇总
A42: 课程目标 | C42: 1 | D42: 2 | E42: 3 | F42: 4 | H42: 5 | J42: 6
A43: 目标分值 | C43: 1 | D43: 2 | E43: 0.5 | F43: 0.5 | H43: 0.5 | J43: 0.5
A44: 得分 | C44: =过程评分表!K29*50%+'答辩评分表 '!J12*50% -> 0.8 | D44: =过程评分表!K30*50%+'答辩评分表 '!J13*50% -> 1.4 | E44: =过程评分表!K31*50%+'答辩评分表 '!J14*50% -> 0.4 | F44: =过程评分表!K32*25%+'答辩评分表 '!J15*25%+('团队合作自评-互评表'!F41*40%+'团队合作自评-互评表'!F85*60%)/50*0.5*50% -> 0.35 | H44: =过程评分表!K33*25%+'答辩评分表 '!J16*25%+('团队合作自评-互评表'!F42*40%+'团队合作自评-互评表'!F86*60%)/50*0.5*50% -> 0.375 | J44: =过程评分表!K34*50%+'答辩评分表 '!J17*50% -> 0.35
A46: 评语：
A47: 经过程、答辩和团队综合评定，该同学课设完成情况达到了课设任务书要求，其答辩和课设论文也达到了专业课设论文的要求，故答辩组一致同意下列的成绩。
A49: 课程设计成绩: | C49: =G40 -> 良好
...

Sheet 信息汇总表
A1: 填表说明：表格内容是自动生成的，和课程负责人要求提交的表格形式一致。
A2: 学号 | B2: 姓名 | C2: 班级 | D2: 指导教师 | E2: 团队编号 | F2: 团队角色 | G2: 成绩 | H2: 目标1 | I2: 目标2 | J2: 目标3 | K2: 目标4 | L2: 目标5 | M2: 目标6 | N2: 项目名称
A3: =基础信息表!E6 -> 0 | B3: =基础信息表!D6 -> 0 | C3: =基础信息表!F6 -> 自动化2301 | D3: =基础信息表!B8 -> 王艳辉 | E3: =基础信息表!B6 -> 0901 | F3: =基础信息表!C6 -> 负责人 | G3: =成绩评定单!C23 -> 中等 | H3: =成绩评定单!C18 -> 0.8 | I3: =成绩评定单!D18 -> 1.4 | J3: =成绩评定单!E18 -> 0.4 | K3: =成绩评定单!F18 -> 0.45 | L3: =成绩评定单!H18 -> 0.475 | M3: =成绩评定单!J18 -> 0.35 | N3: =基础信息表!C3 -> 0
A4: =基础信息表!E7 -> 0 | B4: =基础信息表!D7 -> 0 | C4: =基础信息表!F7 -> 自动化2301 | D4: =基础信息表!B8 -> 王艳辉 | E4: =基础信息表!B6 -> 0901 | F4: =基础信息表!C7 -> 成员1 | G4: =成绩评定单!C49 -> 良好 | H4: =成绩评定单!C44 -> 0.8 | I4: =成绩评定单!D44 -> 1.4 | J4: =成绩评定单!E44 -> 0.4 | K4: =成绩评定单!F44 -> 0.35 | L4: =成绩评定单!H44 -> 0.375 | M4: =成绩评定单!J44 -> 0.35 | N4: =基础信息表!C3 -> 0
A5: =基础信息表!E8 -> 0 | B5: =基础信息表!D8 -> 0 | C5: =基础信息表!F8 -> 自动化2301 | D5: =基础信息表!B8 -> 王艳辉 | E5: =基础信息表!B6 -> 0901 | F5: =基础信息表!C8 -> 成员2 | G5: =成绩评定单!C75 -> 中等 | H5: =成绩评定单!C70 -> 0.7 | I5: =成绩评定单!D70 -> 1.4 | J5: =成绩评定单!E70 -> 0.4 | K5: =成绩评定单!F70 -> 0.3 | L5: =成绩评定单!H70 -> 0.375 | M5: =成绩评定单!J70 -> 0.35 | N5: =基础信息表!C3 -> 0
